{"trial_id": "26", "hyperparameters": {"space": [{"class_name": "Int", "config": {"name": "units", "default": null, "conditions": [], "min_value": 32, "max_value": 512, "step": 32, "sampling": "linear"}}, {"class_name": "Int", "config": {"name": "layers", "default": null, "conditions": [], "min_value": 1, "max_value": 2, "step": 1, "sampling": "linear"}}, {"class_name": "Choice", "config": {"name": "activation", "default": "relu", "conditions": [], "values": ["relu", "tanh"], "ordered": false}}, {"class_name": "Boolean", "config": {"name": "dropout", "default": false, "conditions": []}}, {"class_name": "Float", "config": {"name": "lr", "default": 0.0001, "conditions": [], "min_value": 0.0001, "max_value": 0.01, "step": null, "sampling": "log"}}], "values": {"units": 512, "layers": 1, "activation": "relu", "dropout": false, "lr": 0.01}}, "metrics": {"metrics": {}}, "score": null, "best_step": 0, "status": "FAILED", "message": "Traceback (most recent call last):\n  File \"C:\\Users\\rs3753e\\Anaconda3\\envs\\tf_gpu\\lib\\site-packages\\keras_tuner\\engine\\base_tuner.py\", line 266, in _try_run_and_update_trial\n    self._run_and_update_trial(trial, *fit_args, **fit_kwargs)\n  File \"C:\\Users\\rs3753e\\Anaconda3\\envs\\tf_gpu\\lib\\site-packages\\keras_tuner\\engine\\base_tuner.py\", line 231, in _run_and_update_trial\n    results = self.run_trial(trial, *fit_args, **fit_kwargs)\n  File \"C:\\Users\\rs3753e\\Anaconda3\\envs\\tf_gpu\\lib\\site-packages\\keras_tuner\\engine\\tuner.py\", line 287, in run_trial\n    obj_value = self._build_and_fit_model(trial, *args, **copied_kwargs)\n  File \"C:\\Users\\rs3753e\\Anaconda3\\envs\\tf_gpu\\lib\\site-packages\\keras_tuner\\engine\\tuner.py\", line 214, in _build_and_fit_model\n    results = self.hypermodel.fit(hp, model, *args, **kwargs)\n  File \"C:\\Users\\rs3753e\\Anaconda3\\envs\\tf_gpu\\lib\\site-packages\\keras_tuner\\engine\\hypermodel.py\", line 144, in fit\n    return model.fit(*args, **kwargs)\n  File \"C:\\Users\\rs3753e\\Anaconda3\\envs\\tf_gpu\\lib\\site-packages\\tensorflow\\python\\keras\\engine\\training.py\", line 1239, in fit\n    callbacks.on_epoch_end(epoch, epoch_logs)\n  File \"C:\\Users\\rs3753e\\Anaconda3\\envs\\tf_gpu\\lib\\site-packages\\tensorflow\\python\\keras\\callbacks.py\", line 434, in on_epoch_end\n    callback.on_epoch_end(epoch, logs)\n  File \"C:\\Users\\rs3753e\\Anaconda3\\envs\\tf_gpu\\lib\\site-packages\\keras_tuner\\engine\\tuner_utils.py\", line 217, in on_epoch_end\n    self._save_model()\n  File \"C:\\Users\\rs3753e\\Anaconda3\\envs\\tf_gpu\\lib\\site-packages\\keras_tuner\\engine\\tuner_utils.py\", line 224, in _save_model\n    self.model.save_weights(write_filepath)\n  File \"C:\\Users\\rs3753e\\Anaconda3\\envs\\tf_gpu\\lib\\site-packages\\tensorflow\\python\\keras\\engine\\training.py\", line 2255, in save_weights\n    checkpoint_management.update_checkpoint_state_internal(\n  File \"C:\\Users\\rs3753e\\Anaconda3\\envs\\tf_gpu\\lib\\site-packages\\tensorflow\\python\\training\\checkpoint_management.py\", line 248, in update_checkpoint_state_internal\n    file_io.atomic_write_string_to_file(coord_checkpoint_filename,\n  File \"C:\\Users\\rs3753e\\Anaconda3\\envs\\tf_gpu\\lib\\site-packages\\tensorflow\\python\\lib\\io\\file_io.py\", line 648, in atomic_write_string_to_file\n    rename(temp_pathname, filename, overwrite)\n  File \"C:\\Users\\rs3753e\\Anaconda3\\envs\\tf_gpu\\lib\\site-packages\\tensorflow\\python\\lib\\io\\file_io.py\", line 607, in rename\n    rename_v2(oldname, newname, overwrite)\n  File \"C:\\Users\\rs3753e\\Anaconda3\\envs\\tf_gpu\\lib\\site-packages\\tensorflow\\python\\lib\\io\\file_io.py\", line 623, in rename_v2\n    _pywrap_file_io.RenameFile(\ntensorflow.python.framework.errors_impl.UnknownError: Failed to rename: .\\basian_search\\trial_26\\checkpoint.tmp1902e945ca104ef5887201cf7242fcda to: .\\basian_search\\trial_26\\checkpoint : Zugriff verweigert\r\n; Input/output error\n"}