{"trial_id": "13", "hyperparameters": {"space": [{"class_name": "Int", "config": {"name": "units", "default": null, "conditions": [], "min_value": 32, "max_value": 512, "step": 32, "sampling": "linear"}}, {"class_name": "Int", "config": {"name": "layers", "default": null, "conditions": [], "min_value": 1, "max_value": 2, "step": 1, "sampling": "linear"}}, {"class_name": "Choice", "config": {"name": "activation", "default": "relu", "conditions": [], "values": ["relu", "tanh"], "ordered": false}}, {"class_name": "Boolean", "config": {"name": "dropout", "default": false, "conditions": []}}, {"class_name": "Float", "config": {"name": "lr", "default": 0.0001, "conditions": [], "min_value": 0.0001, "max_value": 0.01, "step": null, "sampling": "log"}}], "values": {"units": 256, "layers": 1, "activation": "relu", "dropout": true, "lr": 0.00030742379337027044}}, "metrics": {"metrics": {}}, "score": null, "best_step": 0, "status": "FAILED", "message": "Traceback (most recent call last):\n  File \"C:\\Users\\rs3753e\\Anaconda3\\envs\\tf_gpu\\lib\\site-packages\\keras_tuner\\engine\\base_tuner.py\", line 266, in _try_run_and_update_trial\n    self._run_and_update_trial(trial, *fit_args, **fit_kwargs)\n  File \"C:\\Users\\rs3753e\\Anaconda3\\envs\\tf_gpu\\lib\\site-packages\\keras_tuner\\engine\\base_tuner.py\", line 231, in _run_and_update_trial\n    results = self.run_trial(trial, *fit_args, **fit_kwargs)\n  File \"C:\\Users\\rs3753e\\Anaconda3\\envs\\tf_gpu\\lib\\site-packages\\keras_tuner\\engine\\tuner.py\", line 287, in run_trial\n    obj_value = self._build_and_fit_model(trial, *args, **copied_kwargs)\n  File \"C:\\Users\\rs3753e\\Anaconda3\\envs\\tf_gpu\\lib\\site-packages\\keras_tuner\\engine\\tuner.py\", line 214, in _build_and_fit_model\n    results = self.hypermodel.fit(hp, model, *args, **kwargs)\n  File \"C:\\Users\\rs3753e\\Anaconda3\\envs\\tf_gpu\\lib\\site-packages\\keras_tuner\\engine\\hypermodel.py\", line 144, in fit\n    return model.fit(*args, **kwargs)\n  File \"C:\\Users\\rs3753e\\Anaconda3\\envs\\tf_gpu\\lib\\site-packages\\tensorflow\\python\\keras\\engine\\training.py\", line 1239, in fit\n    callbacks.on_epoch_end(epoch, epoch_logs)\n  File \"C:\\Users\\rs3753e\\Anaconda3\\envs\\tf_gpu\\lib\\site-packages\\tensorflow\\python\\keras\\callbacks.py\", line 434, in on_epoch_end\n    callback.on_epoch_end(epoch, logs)\n  File \"C:\\Users\\rs3753e\\Anaconda3\\envs\\tf_gpu\\lib\\site-packages\\keras_tuner\\engine\\tuner_utils.py\", line 217, in on_epoch_end\n    self._save_model()\n  File \"C:\\Users\\rs3753e\\Anaconda3\\envs\\tf_gpu\\lib\\site-packages\\keras_tuner\\engine\\tuner_utils.py\", line 224, in _save_model\n    self.model.save_weights(write_filepath)\n  File \"C:\\Users\\rs3753e\\Anaconda3\\envs\\tf_gpu\\lib\\site-packages\\tensorflow\\python\\keras\\engine\\training.py\", line 2253, in save_weights\n    self._trackable_saver.save(filepath, session=session, options=options)\n  File \"C:\\Users\\rs3753e\\Anaconda3\\envs\\tf_gpu\\lib\\site-packages\\tensorflow\\python\\training\\tracking\\util.py\", line 1262, in save\n    save_path, new_feed_additions = self._save_cached_when_graph_building(\n  File \"C:\\Users\\rs3753e\\Anaconda3\\envs\\tf_gpu\\lib\\site-packages\\tensorflow\\python\\training\\tracking\\util.py\", line 1208, in _save_cached_when_graph_building\n    save_op = saver.save(file_prefix, options=options)\n  File \"C:\\Users\\rs3753e\\Anaconda3\\envs\\tf_gpu\\lib\\site-packages\\tensorflow\\python\\training\\saving\\functional_saver.py\", line 300, in save\n    return save_fn()\n  File \"C:\\Users\\rs3753e\\Anaconda3\\envs\\tf_gpu\\lib\\site-packages\\tensorflow\\python\\training\\saving\\functional_saver.py\", line 286, in save_fn\n    return gen_io_ops.merge_v2_checkpoints(\n  File \"C:\\Users\\rs3753e\\Anaconda3\\envs\\tf_gpu\\lib\\site-packages\\tensorflow\\python\\ops\\gen_io_ops.py\", line 501, in merge_v2_checkpoints\n    return merge_v2_checkpoints_eager_fallback(\n  File \"C:\\Users\\rs3753e\\Anaconda3\\envs\\tf_gpu\\lib\\site-packages\\tensorflow\\python\\ops\\gen_io_ops.py\", line 526, in merge_v2_checkpoints_eager_fallback\n    _result = _execute.execute(b\"MergeV2Checkpoints\", 0, inputs=_inputs_flat,\n  File \"C:\\Users\\rs3753e\\Anaconda3\\envs\\tf_gpu\\lib\\site-packages\\tensorflow\\python\\eager\\execute.py\", line 59, in quick_execute\n    tensors = pywrap_tfe.TFE_Py_Execute(ctx._handle, device_name, op_name,\ntensorflow.python.framework.errors_impl.UnknownError: Failed to rename: .\\basian_search\\trial_13\\checkpoint_temp/part-00000-of-00001.data-00000-of-00001 to: .\\basian_search\\trial_13\\checkpoint.data-00000-of-00001 : Zugriff verweigert\r\n; Input/output error [Op:MergeV2Checkpoints]\n"}